Workbook

Sheet INSTRUCTIONS
A1: FY2026 BUDGET TEMPLATE — TRUE SPORTS
A4: HOW TO USE THIS TEMPLATE
A6: 1. BY REP | B6: Enter each rep's total annual budget in USD (column E, blue cells). Rep Team column classifies Elite/Retail/Dual.
B7: CAD column auto-calculates at 1.3699 FX rate.
A9: 2. BY CATEGORY | B9: Break down each rep's budget across 5 product categories.
B10: Category Total (col G) should match their Rep Budget (col H, linked from BY REP).
A12: 3. BY REGION | B12: Auto-calculated — no input needed. Pulls from BY REP.
A14: 4. KEY ACCOUNTS | B14: Enter budget targets for each Key Account retailer.
A16: 5. CHANNEL BUDGETS | B16: Enter budget targets by channel: DTC, Elite, Key Account, Specialty, Other.
A18: NOTES | B18: Removed reps: Corey Gregory (→ Dave McNally), Steve Sutherland (→ Dave McNally), Rich Vanbellinger (→ Dave Campbell). Added: Lucas Gore (Elite), PHILIPPE BOUDREAULT MCNICOLL (EU). ROW region added as placeholder.
A19: Blue text on yellow | B19: Input cell (enter your numbers here)
A20: Black text | B20: Formula (auto-calculated, do not edit)
A21: Green text | B21: Cross-sheet link
A23: CURRENCY | B23: All inputs in USD. CAD columns auto-convert at FX = 1.3699.
B24: To change FX rate, update the formulas in each sheet.
A26: NOTES | B26: This file feeds the True Sports Performance Dashboard.
B27: Once complete, budgets will be locked into the dashboard for the fiscal year.

Sheet BY REP
A1: FY2026 Budget — By Sales Rep
A2: Enter annual budget for each rep in USD (blue cells). Rep Team: Elite / Retail / Dual.
A4: Rep Name | B4: Region | C4: Country | D4: Rep Team | E4: FY2026 Budget (USD) | F4: FY2026 Budget (CAD) | G4: Notes
A5: Brad Savelson | B5: CAN | C5: CA | D5: Retail | E5: 1734334 | F5: =IF(E5="","",E5*1.3699) -> 2375864.1
A6: Brent Hobday | B6: CAN | C6: CA | D6: Retail | E6: 1168073 | F6: =IF(E6="","",E6*1.3699) -> 1600143.2
A7: Carl Menard | B7: CAN | C7: CA | D7: Retail | F7: =IF(E7="","",E7*1.3699)
A8: Greg Pettis | B8: CAN | C8: CA | D8: Retail | E8: 1003929.5 | F8: =IF(E8="","",E8*1.3699) -> 1375283
A9: JEFF LYNCH | B9: CAN | C9: CA | D9: Retail | E9: 1236510.5 | F9: =IF(E9="","",E9*1.3699) -> 1693895.7
A10: Key Accounts Canada | B10: CAN | C10: CA | D10: Retail | E10: 5510478 | F10: =IF(E10="","",E10*1.3699) -> 7548803.8
A11: Marc-Andre Bellehumeur | B11: CAN | C11: CA | D11: Retail | E11: 2307405.5 | F11: =IF(E11="","",E11*1.3699) -> 3160914.8
A12: Mario Richard | B12: CAN | C12: CA | D12: Retail | E12: 1795191.2 | F12: =IF(E12="","",E12*1.3699) -> 2459232.4
A13: Mario Therrien | B13: CAN | C13: CA | D13: Elite | E13: 750000 | F13: =IF(E13="","",E13*1.3699) -> 1027425
A14: Scott Sissions | B14: CAN | C14: CA | D14: Retail | E14: 1516940 | F14: =IF(E14="","",E14*1.3699) -> 2078056.1
A15: WES HUETHER | B15: CAN | C15: CA | D15: Retail | E15: 809752.5 | F15: =IF(E15="","",E15*1.3699) -> 1109279.9 | L15: =L16*1.5 -> 155662.5
A16: Adam Berkhoel | B16: CAN | C16: CA | D16: Elite | E16: 750000 | F16: =IF(E16="","",E16*1.3699) -> 1027425 | K16: 830200 | L16: =K16/8 -> 103775 | M16: =L16/2 -> 51887.5 | N16: =M16*2 -> 103775
A17: DAVE MCNALLY | B17: USA | C17: US | D17: Retail | F17: =IF(E17="","",E17*1.3699) | L17: =L15*4 -> 622650 | M17: =M16*4 -> 207550
A18: Dave Campbell | B18: CAN | C18: CA | D18: Elite | E18: 750000 | F18: =IF(E18="","",E18*1.3699) -> 1027425
A19: Jesse Nifong (Hockey) | B19: USA | C19: US | D19: Retail | E19: 218738.09 | F19: =IF(E19="","",E19*1.3699) -> 299649.31 | L19: =L17+M17 -> 830200
A20: Jon Nassoura | B20: USA | C20: US | D20: Elite | E20: 1000000 | F20: =IF(E20="","",E20*1.3699) -> 1369900
A21: Key Accounts US | B21: USA | C21: US | D21: Retail | E21: 9049259 | F21: =IF(E21="","",E21*1.3699) -> 12396580
A22: Lucas Gore | B22: USA | C22: US | D22: Elite | E22: 1000000 | F22: =IF(E22="","",E22*1.3699) -> 1369900
A23: MITCHELL WALKER | B23: USA | C23: US | D23: Elite | E23: 1000000 | F23: =IF(E23="","",E23*1.3699) -> 1369900
A24: Matt Shaw | B24: USA | C24: US | D24: Retail | E24: 1742900 | F24: =IF(E24="","",E24*1.3699) -> 2387598.7
A25: SCOTT BROWN | B25: USA | C25: US | D25: Dual | F25: =IF(E25="","",E25*1.3699)
A26: SCOTT WALKER | B26: CAN | C26: CA | D26: Elite | E26: 750000 | F26: =IF(E26="","",E26*1.3699) -> 1027425
A27: Steve Boersma | B27: USA | C27: US | D27: Retail | E27: 1526577 | F27: =IF(E27="","",E27*1.3699) -> 2091257.8
A28: VINCENT PIZZO | B28: USA | C28: US | D28: Retail | E28: 309118.55 | F28: =IF(E28="","",E28*1.3699) -> 423461.5
A29: Zac Lampson | B29: USA | C29: US | D29: Retail | E29: 1805680.2 | F29: =IF(E29="","",E29*1.3699) -> 2473601.3
A30: Andreas Lindqvist | B30: EU | C30: EU | D30: Retail | E30: 830200 | F30: =IF(E30="","",E30*1.3699) -> 1137291
A31: Andrew McPherson | B31: EU | C31: EU | D31: Retail | E31: 830200 | F31: =IF(E31="","",E31*1.3699) -> 1137291
A32: Andris Stepins | B32: EU | C32: EU | D32: Retail | E32: 830200 | F32: =IF(E32="","",E32*1.3699) -> 1137291
A33: Filippo Dal Ben | B33: EU | C33: EU | D33: Retail | E33: 830200 | F33: =IF(E33="","",E33*1.3699) -> 1137291
A34: Jonathan Weaver | B34: EU | C34: EU | D34: Retail | E34: 830200 | F34: =IF(E34="","",E34*1.3699) -> 1137291
A35: PETTERI LINNONMAA | B35: EU | C35: EU | D35: Retail | E35: 830200 | F35: =IF(E35="","",E35*1.3699) -> 1137291
A36: PHILIPPE BOUDREAULT MCNICOLL | B36: EU | C36: EU | D36: Retail | E36: 830200 | F36: =IF(E36="","",E36*1.3699) -> 1137291
A37: ProjektS | B37: EU | C37: EU | D37: Retail | E37: 830200 | F37: =IF(E37="","",E37*1.3699) -> 1137291
... A40: NO SALES CREDIT -DTC CAN | B40: CAN | C40: CA | D40: Direct | E40: 1109434.1 | F40: =IF(E40="","",E40*1.3699) -> 1519813.8
A41: ROW | B41: ROW | D41: Retail | E41: 1000000 | F41: =IF(E41="","",E41*1.3699) -> 1369900
A43: TOTAL | E43: =SUM(E5:E41) -> 48461721 | F43: =SUM(F5:F40) -> 65017812
A45: CAN Total | E45: =SUMIFS(E5:E41,B5:B41,"CAN") -> 21192048 | F45: =SUMIFS(F5:F38,B5:B38,"CAN") -> 27511173
...

Sheet BY CATEGORY
A1: FY2026 Budget — By Rep × Category
A2: Enter category budgets per rep (USD). Row totals should match BY REP sheet. Blue cells = input.
A4: Rep Name | B4: Sticks | C4: BAGS | D4: OTHER | E4: PROTECTIVE | F4: Custom Skates | G4: Stock Skates | H4: Custom Goalie | I4: Stock Goalie | J4: Category Total | K4: Rep Budget (link)
A5: Brad Savelson | B5: 639115 | C5: 23761.5 | D5: 32485 | E5: 75726.55 | F5: 173740 | G5: 250400.95 | H5: 261705 | I5: 277400 | J5: =SUM(B5:I5) -> 1734334 | K5: ='BY REP'!E5 -> 1734334
A6: Brent Hobday | B6: 473405 | C6: 34310 | D6: 24528 | E6: 92710 | F6: 85045 | G6: 199655 | H6: 98550 | I6: 159870 | J6: =SUM(B6:I6) -> 1168073 | K6: ='BY REP'!E6 -> 1168073
A7: Carl Menard | J7: =SUM(B7:I7) -> 0 | K7: ='BY REP'!E7 -> 0
A8: Greg Pettis | B8: 495760 | C8: 49910 | D8: 12410 | E8: 86450 | F8: 57669.5 | G8: 152460 | H8: 40880 | I8: 108390 | J8: =SUM(B8:I8) -> 1003929.5 | K8: ='BY REP'!E8 -> 1003929.5
A9: JEFF LYNCH | B9: 368650 | C9: 21827 | D9: 9964.5 | E9: 64240 | F9: 97309 | G9: 182500 | H9: 231775 | I9: 260245 | J9: =SUM(B9:I9) -> 1236510.5 | K9: ='BY REP'!E9 -> 1236510.5
A10: Key Accounts Canada | B10: 3538018 | C10: 185055 | D10: 27375 | E10: 615755 | F10: 213525 | G10: 335800 | H10: 43800 | I10: 551150 | J10: =SUM(B10:I10) -> 5510478 | K10: ='BY REP'!E10 -> 5510478
A11: Marc-Andre Bellehumeur | B11: 813762.5 | C11: 40843.5 | D11: 61685 | E11: 170710.5 | F11: 85629 | G11: 587285 | H11: 176660 | I11: 370830 | J11: =SUM(B11:I11) -> 2307405.5 | K11: ='BY REP'!E11 -> 2307405.5
A12: Mario Richard | B12: 728905 | C12: 39894.5 | D12: 20634.18 | E12: 127129.5 | F12: 140160 | G12: 370219.5 | H12: 116800 | I12: 251448.5 | J12: =SUM(B12:I12) -> 1795191.2 | K12: ='BY REP'!E12 -> 1795191.2
A13: Mario Therrien | B13: 50000 | F13: 200000 | H13: 500000 | J13: =SUM(B13:I13) -> 750000 | K13: ='BY REP'!E13 -> 750000
A14: Scott Sissions | B14: 398653 | C14: 32959.5 | D14: 15330 | E14: 80519 | F14: 191771 | G14: 253857.5 | H14: 332880 | I14: 210970 | J14: =SUM(B14:I14) -> 1516940 | K14: ='BY REP'!E14 -> 1516940
A15: WES HUETHER | B15: 356605 | C15: 13541.5 | D15: 15111 | E15: 50735 | F15: 58035 | G15: 146000 | H15: 62050 | I15: 107675 | J15: =SUM(B15:I15) -> 809752.5 | K15: ='BY REP'!E15 -> 809752.5
A16: Adam Berkhoel | B16: 50000 | F16: 200000 | H16: 500000 | J16: =SUM(B16:I16) -> 750000 | K16: ='BY REP'!E16 -> 750000
A17: DAVE MCNALLY | J17: =SUM(B17:I17) -> 0 | K17: ='BY REP'!E17 -> 0
A18: Dave Campbell | B18: 50000 | F18: 200000 | H18: 500000 | J18: =SUM(B18:I18) -> 750000 | K18: ='BY REP'!E18 -> 750000
A19: Jesse Nifong (Hockey) | B19: 67112.61 | C19: 1502.6 | D19: 0 | E19: 37707.509 | F19: 3650 | G19: 96467 | H19: 0 | I19: 12298.05 | J19: =SUM(B19:I19) -> 218737.77 | K19: ='BY REP'!E19 -> 218738.09
A20: Jon Nassoura | B20: 100000 | F20: 300000 | H20: 600000 | J20: =SUM(B20:I20) -> 1000000 | K20: ='BY REP'!E20 -> 1000000
A21: Key Accounts US | B21: 4696311.5 | C21: 60294 | D21: 193551 | E21: 297478.24 | F21: 1363176.3 | G21: 207951.2 | H21: 846652.9 | I21: 1383843.8 | J21: =SUM(B21:I21) -> 9049259 | K21: ='BY REP'!E21 -> 9049259
A22: Lucas Gore | B22: 100000 | F22: 300000 | H22: 600000 | J22: =SUM(B22:I22) -> 1000000 | K22: ='BY REP'!E22 -> 1000000
A23: MITCHELL WALKER | B23: 50000 | F23: 200000 | H23: 500000 | J23: =SUM(B23:I23) -> 750000 | K23: ='BY REP'!E23 -> 1000000
A24: Matt Shaw | B24: 658800 | C24: 31500 | D24: 36650 | E24: 201700 | F24: 197250 | G24: 207700 | H24: 274400 | I24: 134900 | J24: =SUM(B24:I24) -> 1742900 | K24: ='BY REP'!E24 -> 1742900
A25: SCOTT BROWN | J25: =SUM(B25:I25) -> 0 | K25: ='BY REP'!E25 -> 0
A26: SCOTT WALKER | B26: 100000 | F26: 300000 | H26: 600000 | J26: =SUM(B26:I26) -> 1000000 | K26: ='BY REP'!E26 -> 750000
A27: Steve Boersma | B27: 586500 | C27: 45625 | D27: 28450 | E27: 151100 | F27: 189020 | G27: 274532 | H27: 136500 | I27: 114850 | J27: =SUM(B27:I27) -> 1526577 | K27: ='BY REP'!E27 -> 1526577
A28: VINCENT PIZZO | B28: 88599.63 | C28: 1121.4 | D28: 3299.97 | E28: 8492.47 | F28: 15555 | G28: 4619 | H28: 49602 | I28: 137829.3 | J28: =SUM(B28:I28) -> 309118.77 | K28: ='BY REP'!E28 -> 309118.55
A29: Zac Lampson | B29: 458377.01 | C29: 41389.961 | D29: 96799.495 | E29: 133380.67 | F29: 257000 | G29: 673233.05 | H29: 61500 | I29: 84000 | J29: =SUM(B29:I29) -> 1805680.2 | K29: ='BY REP'!E29 -> 1805680.2
A30: Andreas Lindqvist | B30: 155662.5 | C30: 51887.5 | D30: 51887.5 | E30: 51887.5 | F30: 103775 | G30: 155662.5 | H30: 103775 | I30: 155662.5 | J30: =SUM(B30:I30) -> 830200 | K30: ='BY REP'!E30 -> 830200
A31: Andrew McPherson | B31: 155662.5 | C31: 51887.5 | D31: 51887.5 | E31: 51887.5 | F31: 103775 | G31: 155662.5 | H31: 103775 | I31: 155662.5 | J31: =SUM(B31:I31) -> 830200 | K31: ='BY REP'!E31 -> 830200
A32: Andris Stepins | B32: 155662.5 | C32: 51887.5 | D32: 51887.5 | E32: 51887.5 | F32: 103775 | G32: 155662.5 | H32: 103775 | I32: 155662.5 | J32: =SUM(B32:I32) -> 830200 | K32: ='BY REP'!E32 -> 830200
A33: Filippo Dal Ben | B33: 155662.5 | C33: 51887.5 | D33: 51887.5 | E33: 51887.5 | F33: 103775 | G33: 155662.5 | H33: 103775 | I33: 155662.5 | J33: =SUM(B33:I33) -> 830200 | K33: ='BY REP'!E33 -> 830200
A34: Jonathan Weaver | B34: 155662.5 | C34: 51887.5 | D34: 51887.5 | E34: 51887.5 | F34: 103775 | G34: 155662.5 | H34: 103775 | I34: 155662.5 | J34: =SUM(B34:I34) -> 830200 | K34: ='BY REP'!E34 -> 830200
A35: PETTERI LINNONMAA | B35: 155662.5 | C35: 51887.5 | D35: 51887.5 | E35: 51887.5 | F35: 103775 | G35: 155662.5 | H35: 103775 | I35: 155662.5 | J35: =SUM(B35:I35) -> 830200 | K35: ='BY REP'!E35 -> 830200
A36: PHILIPPE BOUDREAULT MCNICOLL | B36: 155662.5 | C36: 51887.5 | D36: 51887.5 | E36: 51887.5 | F36: 103775 | G36: 155662.5 | H36: 103775 | I36: 155662.5 | J36: =SUM(B36:I36) -> 830200 | K36: ='BY REP'!E36 -> 830200
A37: ProjektS | B37: 155662.5 | C37: 51887.5 | D37: 51887.5 | E37: 51887.5 | F37: 103775 | G37: 155662.5 | H37: 103775 | I37: 155662.5 | J37: =SUM(B37:I37) -> 830200 | K37: ='BY REP'!E37 -> 830200
A38: Tilen Smolnikar | B38: 155662.5 | C38: 51887.5 | D38: 51887.5 | E38: 51887.5 | F38: 103775 | G38: 155662.5 | H38: 103775 | I38: 155662.5 | J38: =SUM(B38:I38) -> 830200 | K38: ='BY REP'!E38 -> 830200
... A41: ROW | B41: 125000 | C41: 125000 | D41: 125000 | E41: 125000 | F41: 125000 | G41: 125000 | H41: 125000 | I41: 125000 | J41: =SUM(B41:I41) -> 1000000 | K41: ='BY REP'!E41 -> 1000000
A42: TOTAL | B42: =SUM(B5:B41) -> 16676416 | C42: =SUM(C5:C41) -> 1497402.2 | D42: =SUM(D5:D41) -> 1452139.9 | E42: =SUM(E5:E41) -> 3067701.2 | F42: =SUM(F5:F41) -> 6169389.1 | G42: =SUM(G5:G41) -> 5750522 | H42: =SUM(H5:H41) -> 7874609.2 | I42: =SUM(I5:I41) -> 5973541.4 | J42: =SUM(J5:J41) -> 48461721 | K42: =SUM(K5:K40) -> 47461721
A43: Variance (Cat Total vs Rep Budget)

Sheet BY REGION
A1: FY2026 Budget — By Region
A2: Auto-calculated from BY REP sheet. No manual entry needed.
A4: Region | B4: Budget (USD) | C4: Budget (CAD) | D4: % of Total
A5: CAN | B5: 21192048 | C5: =B5*1.3699 -> 29030987 | D5: =IF(B$9=0,"-",B5/B$9) -> 0.43729459
A6: USA | B6: 18797873 | C6: =B6*1.3699 -> 25751206 | D6: =IF(B$9=0,"-",B6/B$9) -> 0.38789115
A7: EU | B7: 7471800 | C7: =B7*1.3699 -> 10235619 | D7: =IF(B$9=0,"-",B7/B$9) -> 0.15417942
A8: ROW | B8: 1000000 | C8: =B8*1.3699 -> 1369900 | D8: =IF(B$9=0,"-",B8/B$9) -> 0.020634843
A9: GLOBAL TOTAL | B9: =SUM(B5:B8) -> 48461721 | C9: =SUM(C5:C8) -> 66387712 | D9: =IF(B$9=0,"-",B9/B$9) -> 1

Sheet KEY ACCOUNTS
A1: FY2026 Budget — Key Accounts
A2: Enter budget by Key Account (USD). Blue cells = input.
A4: Key Account | B4: FY2026 Budget (USD) | C4: FY2026 Budget (CAD) | D4: Notes
A5: PRO HOCKEY LIFE | B5: 3286168 | C5: =IF(B5="","",B5*1.3699) -> 4501721.5
A6: SOURCE FOR SPORTS CANADA | B6: 5088976 | C6: =IF(B6="","",B6*1.3699) -> 6971388.2
A7: PURE HOCKEY | B7: 5000000 | C7: =IF(B7="","",B7*1.3699) -> 6849500
A8: MONKEY USA | B8: 3500000 | C8: =IF(B8="","",B8*1.3699) -> 4794650
A9: INDEPENDENTS USA | B9: 2015107.6 | C9: =IF(B9="","",B9*1.3699) -> 2760495.9
A10: FGL FRANCHISE DIVISION | B10: 2774766.5 | C10: =IF(B10="","",B10*1.3699) -> 3801152.6
A11: SPORTS EXCELLENCE CANADA | B11: 1708455.5 | C11: =IF(B11="","",B11*1.3699) -> 2340413.2
A12: INDEPENDENTS CANADA | B12: 1242870.2 | C12: =IF(B12="","",B12*1.3699) -> 1702607.9
A13: SPORTS EXCELLENCE USA | B13: 1637534.6 | C13: =IF(B13="","",B13*1.3699) -> 2243258.7
A14: SOURCE FOR SPORTS USA | B14: 1413866 | C14: =IF(B14="","",B14*1.3699) -> 1936855
A15: SPORT CHEK | B15: 1945450 | C15: =IF(B15="","",B15*1.3699) -> 2665072
A16: MONKEY CANADA | B16: 150000 | C16: =IF(B16="","",B16*1.3699) -> 205485
... A22: FGL CORPORATE DIVISION | B22: 12665.5 | C22: =IF(B22="","",B22*1.3699) -> 17350.468

Sheet SPECIALTY ACCOUNTS
A1: FY2026 Budget — Specialty Accounts
A2: Enter budget by Specialty Account (USD). Blue cells = input.
A4: Specialty Account | B4: FY2026 Budget (USD) | C4: FY2026 Budget (CAD) | D4: Notes
A5: FGL FRANCHISES | B5: 2778111.4 | C5: =IF(B5="","",B5*1.3699) -> 3805734.8
A6: INDEPENDENTS | B6: 3251366.3 | C6: =IF(B6="","",B6*1.3699) -> 4454046.7
A7: SOURCE FOR SPORTS | B7: 7045000 | C7: =IF(B7="","",B7*1.3699) -> 9650945.5
A8: SPORTS EXCELLENCE | B8: 2213000 | C8: =IF(B8="","",B8*1.3699) -> 3031588.7
A9: SPECIALTY TOTAL | B9: =SUM(B5:B8) -> 15287478 | C9: =SUM(C5:C8) -> 20942316

Sheet CHANNEL BUDGETS
A1: FY2026 Budget — By Channel
A2: Enter budget by channel (USD). Blue cells = input.
A4: Channel | B4: FY2026 Budget (USD) | C4: FY2026 Budget (CAD) | D4: Notes
A5: DTC | B5: 2275000 | C5: =IF(B5="","",B5*1.3699) -> 3116522.5
A6: Elite | B6: 6000000 | C6: =IF(B6="","",B6*1.3699) -> 8219400
A7: Key Account N-A | B7: 14287184 | C7: =IF(B7="","",B7*1.3699) -> 19572013
A8: Specialty N-A | B8: 15287478 | C8: =IF(B8="","",B8*1.3699) -> 20942316
A9: Other N-A | B9: 2140259.8 | C9: =IF(B9="","",B9*1.3699) -> 2931942
A10: CHANNEL TOTAL | B10: =SUM(B5:B9) -> 39989921 | C10: =SUM(C5:C9) -> 54782193
