Workbook

Sheet INSTRUCTIONS
A1: FY2026 BUDGET TEMPLATE — TRUE SPORTS
A4: HOW TO USE THIS TEMPLATE
A6: 1. BY REP | B6: Enter each rep's total annual budget in USD (column E, blue cells). Rep Team column classifies Elite/Retail/Dual.
B7: CAD column auto-calculates at 1.3699 FX rate.
A9: 2. BY CATEGORY | B9: Break down each rep's budget across 5 product categories.
B10: Category Total (col G) should match their Rep Budget (col H, linked from BY REP).
A12: 3. BY REGION | B12: Auto-calculated — no input needed. Pulls from BY REP.
A14: 4. KEY ACCOUNTS | B14: Enter budget targets for each Key Account retailer.
A16: 5. CHANNEL BUDGETS | B16: Enter budget targets by channel: DTC, Elite, Key Account, Specialty, Other.
A18: NOTES | B18: Removed reps: Corey Gregory (→ Dave McNally), Steve Sutherland (→ Dave McNally), Rich Vanbellinger (→ Dave Campbell). Added: Lucas Gore (Elite), PHILIPPE BOUDREAULT MCNICOLL (EU). ROW region added as placeholder.
A19: Blue text on yellow | B19: Input cell (enter your numbers here)
A20: Black text | B20: Formula (auto-calculated, do not edit)
A21: Green text | B21: Cross-sheet link
A23: CURRENCY | B23: All inputs in USD. CAD columns auto-convert at FX = 1.3699.
B24: To change FX rate, update the formulas in each sheet.
A26: NOTES | B26: This file feeds the True Sports Performance Dashboard.
B27: Once complete, budgets will be locked into the dashboard for the fiscal year.

Sheet BY REP
A1: FY2026 Budget — By Sales Rep
A2: Enter annual budget for each rep in USD (blue cells). Rep Team: Elite / Retail / Dual.
A4: Rep Name | B4: Region | C4: Country | D4: Rep Team | E4: FY2026 Budget (USD) | F4: FY2026 Budget (CAD) | G4: Notes
A5: Brad Savelson | B5: CAN | C5: CA | D5: Retail | E5: 1734334 | F5: =IF(E5="","",E5*1.3699) -> 2375864.1
A6: Brent Hobday | B6: CAN | C6: CA | D6: Retail | E6: 1168073 | F6: =IF(E6="","",E6*1.3699) -> 1600143.2
A7: Carl Menard | B7: CAN | C7: CA | D7: Retail | F7: =IF(E7="","",E7*1.3699)
A8: Greg Pettis | B8: CAN | C8: CA | D8: Retail | E8: 1003929.5 | F8: =IF(E8="","",E8*1.3699) -> 1375283
A9: JEFF LYNCH | B9: CAN | C9: CA | D9: Retail | E9: 1236510.5 | F9: =IF(E9="","",E9*1.3699) -> 1693895.7
A10: Key Accounts Canada | B10: CAN | C10: CA | D10: Retail | E10: 5510478 | F10: =IF(E10="","",E10*1.3699) -> 7548803.8
A11: Marc-Andre Bellehumeur | B11: CAN | C11: CA | D11: Retail | E11: 2307405.5 | F11: =IF(E11="","",E11*1.3699) -> 3160914.8
A12: Mario Richard | B12: CAN | C12: CA | D12: Retail | E12: 1795191.2 | F12: =IF(E12="","",E12*1.3699) -> 2459232.4
A13: Mario Therrien | B13: CAN | C13: CA | D13: Retail | F13: =IF(E13="","",E13*1.3699)
A14: Scott Sissions | B14: CAN | C14: CA | D14: Retail | E14: 1516940 | F14: =IF(E14="","",E14*1.3699) -> 2078056.1
A15: WES HUETHER | B15: CAN | C15: CA | D15: Retail | E15: 809752.5 | F15: =IF(E15="","",E15*1.3699) -> 1109279.9
A16: Adam Berkhoel | B16: USA | C16: US | D16: Elite | F16: =IF(E16="","",E16*1.3699)
A17: DAVE MCNALLY | B17: USA | C17: US | D17: Retail | F17: =IF(E17="","",E17*1.3699)
A18: Dave Campbell | B18: USA | C18: US | D18: Elite | F18: =IF(E18="","",E18*1.3699)
A19: Jesse Nifong (Hockey) | B19: USA | C19: US | D19: Retail | E19: 218738.09 | F19: =IF(E19="","",E19*1.3699) -> 299649.31
A20: Jon Nassoura | B20: USA | C20: US | D20: Elite | F20: =IF(E20="","",E20*1.3699)
A21: Key Accounts US | B21: USA | C21: US | D21: Retail | E21: 9049259 | F21: =IF(E21="","",E21*1.3699) -> 12396580
A22: Lucas Gore | B22: USA | C22: US | D22: Elite | F22: =IF(E22="","",E22*1.3699)
A23: MITCHELL WALKER | B23: USA | C23: US | D23: Elite | F23: =IF(E23="","",E23*1.3699)
A24: Matt Shaw | B24: USA | C24: US | D24: Retail | E24: 1742900 | F24: =IF(E24="","",E24*1.3699) -> 2387598.7
A25: SCOTT BROWN | B25: USA | C25: US | D25: Dual | F25: =IF(E25="","",E25*1.3699)
A26: SCOTT WALKER | B26: USA | C26: US | D26: Elite | F26: =IF(E26="","",E26*1.3699)
A27: Steve Boersma | B27: USA | C27: US | D27: Dual | E27: 1526577 | F27: =IF(E27="","",E27*1.3699) -> 2091257.8
A28: VINCENT PIZZO | B28: USA | C28: US | D28: Retail | E28: 309118.55 | F28: =IF(E28="","",E28*1.3699) -> 423461.5
A29: Zac Lampson | B29: USA | C29: US | D29: Retail | E29: 1805680.2 | F29: =IF(E29="","",E29*1.3699) -> 2473601.3
A30: Andreas Lindqvist | B30: EU | C30: EU | D30: Retail | F30: =IF(E30="","",E30*1.3699)
A31: Andrew McPherson | B31: EU | C31: EU | D31: Retail | F31: =IF(E31="","",E31*1.3699)
A32: Andris Stepins | B32: EU | C32: EU | D32: Retail | F32: =IF(E32="","",E32*1.3699)
A33: Filippo Dal Ben | B33: EU | C33: EU | D33: Retail | F33: =IF(E33="","",E33*1.3699)
A34: Jonathan Weaver | B34: EU | C34: EU | D34: Retail | F34: =IF(E34="","",E34*1.3699)
A35: PETTERI LINNONMAA | B35: EU | C35: EU | D35: Retail | F35: =IF(E35="","",E35*1.3699)
A36: PHILIPPE BOUDREAULT MCNICOLL | B36: EU | C36: EU | D36: Retail | F36: =IF(E36="","",E36*1.3699)
A37: ProjektS | B37: EU | C37: EU | D37: Retail | F37: =IF(E37="","",E37*1.3699)
A38: Tilen Smolnikar | B38: EU | C38: EU | D38: Retail | F38: =IF(E38="","",E38*1.3699)
A40: TOTAL | E40: =SUM(E5:E38) -> 31734887 | F40: =SUM(F5:F38) -> 43473622
A42: CAN Total | E42: =SUMIFS(E5:E38,B5:B38,"CAN") -> 17082614 | F42: =SUMIFS(F5:F38,B5:B38,"CAN") -> 23401473
A43: USA Total | E43: =SUMIFS(E5:E38,B5:B38,"USA") -> 14652273 | F43: =SUMIFS(F5:F38,B5:B38,"USA") -> 20072149
...

Sheet BY CATEGORY
A1: FY2026 Budget — By Rep × Category
A2: Enter category budgets per rep (USD). Row totals should match BY REP sheet. Blue cells = input.
A4: Rep Name | B4: Sticks | C4: Custom Skates | D4: Stock Skates | E4: Custom Goalie | F4: Stock Goalie | G4: Category Total | H4: Rep Budget (link)
A5: Brad Savelson | B5: 639115 | C5: 173740 | D5: 250400.95 | E5: 261705 | F5: 277400 | G5: =SUM(B5:F5) -> 1602360.9 | H5: ='BY REP'!E5 -> 1734334
A6: Brent Hobday | B6: 473405 | C6: 85045 | D6: 199655 | E6: 98550 | F6: 159870 | G6: =SUM(B6:F6) -> 1016525 | H6: ='BY REP'!E6 -> 1168073
A7: Carl Menard | G7: =SUM(B7:F7) -> 0 | H7: ='BY REP'!E7 -> 0
A8: Greg Pettis | B8: 495760 | C8: 57669.5 | D8: 152460 | E8: 40880 | F8: 108390 | G8: =SUM(B8:F8) -> 855159.5 | H8: ='BY REP'!E8 -> 1003929.5
A9: JEFF LYNCH | B9: 368650 | C9: 97309 | D9: 182500 | E9: 231775 | F9: 260245 | G9: =SUM(B9:F9) -> 1140479 | H9: ='BY REP'!E9 -> 1236510.5
A10: Key Accounts Canada | B10: 3538018 | C10: 213525 | D10: 335800 | E10: 43800 | F10: 551150 | G10: =SUM(B10:F10) -> 4682293 | H10: ='BY REP'!E10 -> 5510478
A11: Marc-Andre Bellehumeur | B11: 813762.5 | C11: 85629 | D11: 587285 | E11: 176660 | F11: 370830 | G11: =SUM(B11:F11) -> 2034166.5 | H11: ='BY REP'!E11 -> 2307405.5
A12: Mario Richard | B12: 728905 | C12: 140160 | D12: 370219.5 | E12: 116800 | F12: 251448.5 | G12: =SUM(B12:F12) -> 1607533 | H12: ='BY REP'!E12 -> 1795191.2
A13: Mario Therrien | G13: =SUM(B13:F13) -> 0 | H13: ='BY REP'!E13 -> 0
A14: Scott Sissions | B14: 398653 | C14: 191771 | D14: 253857.5 | E14: 332880 | F14: 210970 | G14: =SUM(B14:F14) -> 1388131.5 | H14: ='BY REP'!E14 -> 1516940
A15: WES HUETHER | B15: 356605 | C15: 58035 | D15: 146000 | E15: 62050 | F15: 107675 | G15: =SUM(B15:F15) -> 730365 | H15: ='BY REP'!E15 -> 809752.5
A16: Adam Berkhoel | G16: =SUM(B16:F16) -> 0 | H16: ='BY REP'!E16 -> 0
A17: DAVE MCNALLY | G17: =SUM(B17:F17) -> 0 | H17: ='BY REP'!E17 -> 0
A18: Dave Campbell | G18: =SUM(B18:F18) -> 0 | H18: ='BY REP'!E18 -> 0
A19: Jesse Nifong (Hockey) | B19: 67112.61 | C19: 3650 | D19: 96467 | E19: 0 | F19: 12298.05 | G19: =SUM(B19:F19) -> 179527.66 | H19: ='BY REP'!E19 -> 218738.09
A20: Jon Nassoura | G20: =SUM(B20:F20) -> 0 | H20: ='BY REP'!E20 -> 0
A21: Key Accounts US | B21: 4696311.5 | C21: 1363176.3 | D21: 207951.2 | E21: 846652.9 | F21: 1383843.8 | G21: =SUM(B21:F21) -> 8497935.8 | H21: ='BY REP'!E21 -> 9049259
A22: Lucas Gore | G22: =SUM(B22:F22) -> 0 | H22: ='BY REP'!E22 -> 0
A23: MITCHELL WALKER | G23: =SUM(B23:F23) -> 0 | H23: ='BY REP'!E23 -> 0
A24: Matt Shaw | B24: 658800 | C24: 197250 | D24: 207700 | E24: 274400 | F24: 134900 | G24: =SUM(B24:F24) -> 1473050 | H24: ='BY REP'!E24 -> 1742900
A25: SCOTT BROWN | G25: =SUM(B25:F25) -> 0 | H25: ='BY REP'!E25 -> 0
A26: SCOTT WALKER | G26: =SUM(B26:F26) -> 0 | H26: ='BY REP'!E26 -> 0
A27: Steve Boersma | B27: 586500 | C27: 189020 | D27: 274532 | E27: 136500 | F27: 114850 | G27: =SUM(B27:F27) -> 1301402 | H27: ='BY REP'!E27 -> 1526577
A28: VINCENT PIZZO | B28: 88599.63 | C28: 15555 | D28: 4619 | E28: 49602 | F28: 137829.3 | G28: =SUM(B28:F28) -> 296204.93 | H28: ='BY REP'!E28 -> 309118.55
A29: Zac Lampson | B29: 458377.01 | C29: 257000 | D29: 673233.05 | E29: 61500 | F29: 84000 | G29: =SUM(B29:F29) -> 1534110.1 | H29: ='BY REP'!E29 -> 1805680.2
A30: Andreas Lindqvist | G30: =SUM(B30:F30) -> 0 | H30: ='BY REP'!E30 -> 0
A31: Andrew McPherson | G31: =SUM(B31:F31) -> 0 | H31: ='BY REP'!E31 -> 0
A32: Andris Stepins | G32: =SUM(B32:F32) -> 0 | H32: ='BY REP'!E32 -> 0
A33: Filippo Dal Ben | G33: =SUM(B33:F33) -> 0 | H33: ='BY REP'!E33 -> 0
A34: Jonathan Weaver | G34: =SUM(B34:F34) -> 0 | H34: ='BY REP'!E34 -> 0
A35: PETTERI LINNONMAA | G35: =SUM(B35:F35) -> 0 | H35: ='BY REP'!E35 -> 0
A36: PHILIPPE BOUDREAULT MCNICOLL | G36: =SUM(B36:F36) -> 0 | H36: ='BY REP'!E36 -> 0
A37: ProjektS | G37: =SUM(B37:F37) -> 0 | H37: ='BY REP'!E37 -> 0
A38: Tilen Smolnikar | G38: =SUM(B38:F38) -> 0 | H38: ='BY REP'!E38 -> 0
A39: TOTAL | B39: =SUM(B5:B38) -> 14368574 | C39: =SUM(C5:C38) -> 3128534.8 | D39: =SUM(D5:D38) -> 3942680.2 | E39: =SUM(E5:E38) -> 2733754.9 | F39: =SUM(F5:F38) -> 4165699.6 | G39: =SUM(G5:G38) -> 28339244 | H39: =SUM(H5:H38) -> 31734887
A40: Variance (Cat Total vs Rep Budget)

Sheet BY REGION
A1: FY2026 Budget — By Region
A2: Auto-calculated from BY REP sheet. No manual entry needed.
A4: Region | B4: Budget (USD) | C4: Budget (CAD) | D4: % of Total
A5: CAN | B5: =SUMIFS('BY REP'!E5:E38,'BY REP'!B5:B38,"CAN") -> 17082614 | C5: =B5*1.3699 -> 23401473 | D5: =IF(B$9=0,"-",B5/B$9) -> 0.53829132
A6: USA | B6: =SUMIFS('BY REP'!E5:E38,'BY REP'!B5:B38,"USA") -> 14652273 | C6: =B6*1.3699 -> 20072149 | D6: =IF(B$9=0,"-",B6/B$9) -> 0.46170868
A7: EU | B7: =SUMIFS('BY REP'!E5:E38,'BY REP'!B5:B38,"EU") -> 0 | C7: =B7*1.3699 -> 0 | D7: =IF(B$9=0,"-",B7/B$9) -> 0
A8: ROW | B8: =SUMIFS('BY REP'!E5:E38,'BY REP'!B5:B38,"ROW") -> 0 | C8: =B8*1.3699 -> 0 | D8: =IF(B$9=0,"-",B8/B$9) -> 0
A9: GLOBAL TOTAL | B9: =SUM(B5:B8) -> 31734887 | C9: =SUM(C5:C8) -> 43473622

Sheet KEY ACCOUNTS
A1: FY2026 Budget — Key Accounts
A2: Enter budget by Key Account (USD). Blue cells = input.
A4: Key Account | B4: FY2026 Budget (USD) | C4: FY2026 Budget (CAD) | D4: Notes
A5: PRO HOCKEY LIFE | C5: =IF(B5="","",B5*1.3699)
A6: PURE HOCKEY | C6: =IF(B6="","",B6*1.3699)
A7: MONKEY USA | C7: =IF(B7="","",B7*1.3699)
A8: MONKEY CANADA | C8: =IF(B8="","",B8*1.3699)
A9: SPORT CHEK | C9: =IF(B9="","",B9*1.3699)
A10: PIAS USA | C10: =IF(B10="","",B10*1.3699)
A11: PIAS CANADA | C11: =IF(B11="","",B11*1.3699)
A12: PERANIS | C12: =IF(B12="","",B12*1.3699)
A13: Key Accounts Canada | C13: =IF(B13="","",B13*1.3699)
A14: Key Accounts US | C14: =IF(B14="","",B14*1.3699)
A15: KEY ACCOUNTS TOTAL | B15: =SUM(B5:B14) -> 0 | C15: =SUM(C5:C14) -> 0

Sheet SPECIALTY ACCOUNTS
A1: FY2026 Budget — Specialty Accounts
A2: Enter budget by Specialty Account (USD). Blue cells = input.
A4: Specialty Account | B4: FY2026 Budget (USD) | C4: FY2026 Budget (CAD) | D4: Notes
A5: SOURCE FOR SPORTS CANADA | C5: =IF(B5="","",B5*1.3699)
A6: SOURCE FOR SPORTS USA | C6: =IF(B6="","",B6*1.3699)
A7: FGL FRANCHISE DIVISION | C7: =IF(B7="","",B7*1.3699)
A8: SPORTS EXCELLENCE CANADA | C8: =IF(B8="","",B8*1.3699)
A9: SPORTS EXCELLENCE USA | C9: =IF(B9="","",B9*1.3699)
A10: INDEPENDENTS CANADA | C10: =IF(B10="","",B10*1.3699)
A11: INDEPENDENTS USA | C11: =IF(B11="","",B11*1.3699)
A12: HOCKEY HOUND | C12: =IF(B12="","",B12*1.3699)
A13: SPORTS AUX PUCES | C13: =IF(B13="","",B13*1.3699)
A14: SPECIALTY TOTAL | B14: =SUM(B5:B13) -> 0 | C14: =SUM(C5:C13) -> 0

Sheet CHANNEL BUDGETS
A1: FY2026 Budget — By Channel
A2: Enter budget by channel (USD). Blue cells = input.
A4: Channel | B4: FY2026 Budget (USD) | C4: FY2026 Budget (CAD) | D4: Notes
A5: DTC | C5: =IF(B5="","",B5*1.3699)
A6: Elite | C6: =IF(B6="","",B6*1.3699)
A7: Key Account | C7: =IF(B7="","",B7*1.3699)
A8: Specialty | C8: =IF(B8="","",B8*1.3699)
A9: Other | C9: =IF(B9="","",B9*1.3699)
A10: CHANNEL TOTAL | B10: =SUM(B5:B9) -> 0 | C10: =SUM(C5:C9) -> 0
